Workbook

Sheet Vendas
A1: ID_Venda | B1: Produto | C1: Região | D1: Valor | E1: Data | F1: Nome_Vendedor | G1: Ano | H1: Mês
A2: V1001 | B2: Produto B | C2: Sudeste | D2: 437.36 | E2: 44681 | F2: Diego Lima | G2: =YEAR(E2) | H2: =MONTH(E2)
A3: V1002 | B3: Produto C | C3: Sudeste | D3: 3423.29 | E3: 45007 | F3: Bruno Costa | G3: =YEAR(E3) | H3: =MONTH(E3)
A4: V1003 | B4: Produto X | C4: Sudeste | D4: 3652.26 | E4: 45229 | F4: Eva Rocha | G4: =YEAR(E4) | H4: =MONTH(E4)
A5: V1004 | B5: Produto Y | C5: Centro-Oeste | D5: 4727.64 | E5: 45194 | F5: Carla Dias | G5: =YEAR(E5) | H5: =MONTH(E5)
A6: V1005 | B6: Produto X | C6: Nordeste | D6: 4372.35 | E6: 44679 | F6: Bruno Costa | G6: =YEAR(E6) | H6: =MONTH(E6)
A7: V1006 | B7: Produto A | C7: Sul | D7: 4374.75 | E7: 45036 | F7: Carla Dias | G7: =YEAR(E7) | H7: =MONTH(E7)
A8: V1007 | B8: Produto Y | C8: Sudeste | D8: 4117.47 | E8: 44706 | F8: Carla Dias | G8: =YEAR(E8) | H8: =MONTH(E8)
A9: V1008 | B9: Produto B | C9: Norte | D9: 320.68 | E9: 44886 | F9: Carla Dias | G9: =YEAR(E9) | H9: =MONTH(E9)
A10: V1009 | B10: Produto C | C10: Norte | D10: 4598.63 | E10: 45280 | F10: Bruno Costa | G10: =YEAR(E10) | H10: =MONTH(E10)
A11: V1010 | B11: Produto A | C11: Sul | D11: 904.7 | E11: 45291 | F11: Carla Dias | G11: =YEAR(E11) | H11: =MONTH(E11)
A12: V1011 | B12: Produto B | C12: Nordeste | D12: 2884.02 | E12: 44856 | F12: Carla Dias | G12: =YEAR(E12) | H12: =MONTH(E12)
A13: V1012 | B13: Produto X | C13: Centro-Oeste | D13: 4951.64 | E13: 45273 | F13: Bruno Costa | G13: =YEAR(E13) | H13: =MONTH(E13)
... A81: V1080 | B81: Produto X | C81: Centro-Oeste | D81: 3600.66 | E81: 44903 | F81: Ana Silva | G81: =YEAR(E81) | H81: =MONTH(E81)

Sheet Lookup
A1: Chave | B1: Retorno
A2: Produto X | B2: Descrição do Produto X
A3: Produto A | B3: Descrição do Produto A
A4: Produto B | B4: Descrição do Produto B
A5: Produto C | B5: Descrição do Produto C
A6: Produto Y | B6: Descrição do Produto Y

Sheet Análise
A1: KPIs
A2: Descrição | B2: Fórmula (usar no Excel/Sheets)
A3: Receita Total | B3: =SUM(Vendas!D2:D81)
A4: Valor Médio por Venda | B4: =AVERAGE(Vendas!D2:D81)
A5: Número de Vendas | B5: =COUNTA(Vendas!A2:A81)
A6: Maior Venda | B6: =MAX(Vendas!D2:D81)
A7: Menor Venda | B7: =MIN(Vendas!D2:D81)
A9: Totais por Região
A10: Região | B10: Receita
A11: Nordeste | B11: =SUMIF(Vendas!C2:C81, "Nordeste", Vendas!D2:D81)
A12: Sudeste | B12: =SUMIF(Vendas!C2:C81, "Sudeste", Vendas!D2:D81)
A13: Sul | B13: =SUMIF(Vendas!C2:C81, "Sul", Vendas!D2:D81)
A14: Norte | B14: =SUMIF(Vendas!C2:C81, "Norte", Vendas!D2:D81)
A15: Centro-Oeste | B15: =SUMIF(Vendas!C2:C81, "Centro-Oeste", Vendas!D2:D81)
A17: Totais por Produto
A18: Produto | B18: Receita
A19: Produto A | B19: =SUMIF(Vendas!B2:B81, "Produto A", Vendas!D2:D81)
A20: Produto B | B20: =SUMIF(Vendas!B2:B81, "Produto B", Vendas!D2:D81)
A21: Produto C | B21: =SUMIF(Vendas!B2:B81, "Produto C", Vendas!D2:D81)
A22: Produto X | B22: =SUMIF(Vendas!B2:B81, "Produto X", Vendas!D2:D81)
A23: Produto Y | B23: =SUMIF(Vendas!B2:B81, "Produto Y", Vendas!D2:D81)
A25: Totais por Mês (nº do mês)
A26: Mês | B26: Receita
A27: 1 | B27: =SUMIF(Vendas!H2:H81, 1, Vendas!D2:D81)
A28: 2 | B28: =SUMIF(Vendas!H2:H81, 2, Vendas!D2:D81)
A29: 3 | B29: =SUMIF(Vendas!H2:H81, 3, Vendas!D2:D81)
A30: 4 | B30: =SUMIF(Vendas!H2:H81, 4, Vendas!D2:D81)
A31: 5 | B31: =SUMIF(Vendas!H2:H81, 5, Vendas!D2:D81)
A32: 6 | B32: =SUMIF(Vendas!H2:H81, 6, Vendas!D2:D81)
A33: 7 | B33: =SUMIF(Vendas!H2:H81, 7, Vendas!D2:D81)
A34: 8 | B34: =SUMIF(Vendas!H2:H81, 8, Vendas!D2:D81)
A35: 9 | B35: =SUMIF(Vendas!H2:H81, 9, Vendas!D2:D81)
A36: 10 | B36: =SUMIF(Vendas!H2:H81, 10, Vendas!D2:D81)
A37: 11 | B37: =SUMIF(Vendas!H2:H81, 11, Vendas!D2:D81)
A38: 12 | B38: =SUMIF(Vendas!H2:H81, 12, Vendas!D2:D81)
A40: Totais por Vendedor
A41: Vendedor | B41: Receita
A42: Ana Silva | B42: =SUMIF(Vendas!F2:F81, "Ana Silva", Vendas!D2:D81)
A43: Bruno Costa | B43: =SUMIF(Vendas!F2:F81, "Bruno Costa", Vendas!D2:D81)
A44: Carla Dias | B44: =SUMIF(Vendas!F2:F81, "Carla Dias", Vendas!D2:D81)
...

Sheet Atividade Prática – Funções Avançadas
A1: Descrição | B1: Fórmula (em inglês para Google Sheets) | C1: Resultado (será calculado no Sheets)
A2: Somatório Condicional (Nordeste) | B2: =SUMIF(Vendas!C2:C81, "Nordeste", Vendas!D2:D81) | C2: =SUMIF(Vendas!C2:C81, "Nordeste", Vendas!D2:D81)
A3: Somatório Condicional com múltiplos critérios (Produto X, Região Sudeste) | B3: =SUMIFS(Vendas!D2:D81, Vendas!B2:B81, "Produto X", Vendas!C2:C81, "Sudeste") | C3: =SUMIFS(Vendas!D2:D81, Vendas!B2:B81, "Produto X", Vendas!C2:C81, "Sudeste")
A4: PROCV — buscar Nome_Vendedor a partir de ID_Venda (VLOOKUP exemplo) | B4: =VLOOKUP("V1001", Vendas!A2:F81, 6, FALSE) | C4: =VLOOKUP("V1001", Vendas!A2:F81, 6, FALSE)
A5: PROCX equivalente — INDEX/MATCH para descrição do produto | B5: =INDEX(Lookup!B2:B6, MATCH("Produto X", Lookup!A2:A6, 0)) | C5: =INDEX(Lookup!B2:B6, MATCH("Produto X", Lookup!A2:A6, 0))
A6: Ano da venda (coluna E) | B6: =YEAR(Vendas!E2) | C6: =YEAR(Vendas!E2)
A7: Mês da venda (coluna E) | B7: =MONTH(Vendas!E2) | C7: =MONTH(Vendas!E2)
A8: Dia da venda (coluna E) | B8: =DAY(Vendas!E2) | C8: =DAY(Vendas!E2)
A9: Desafio — Soma Produto X entre 01/01/2023 e 31/12/2023 | B9: =SUMIFS(Vendas!D2:D81, Vendas!B2:B81, "Produto X", Vendas!E2:E81, ">=2023-01-01", Vendas!E2:E81, "<=2023-12-31") | C9: =SUMIFS(Vendas!D2:D81, Vendas!B2:B81, "Produto X", Vendas!E2:E81, ">=2023-01-01", Vendas!E2:E81, "<=2023-12-31")
A10: Produto com maior receita (INDEX/MATCH a partir da tabela acima) | B10: =INDEX(Análise!A50:A54, MATCH(MAX(Análise!B50:B54), Análise!B50:B54, 0)) | C10: =INDEX(Análise!A50:A54, MATCH(MAX(Análise!B50:B54), Análise!B50:B54, 0))
